Workbook

Sheet Summary
A1: EXECUTIVE SUMMARY — GLP-1 subsector valuation (AMGN + VKTX)
A3: Stock | B3: Current | C3: Fair value (base) | D3: FV range | E3: Up/(down) | F3: Key swing factor
A4: Amgen (AMGN) | B4: 339 | C4: 282.1 | D4: $208–322 | E4: -0.1678592 | F4: Base-business durability + terminal WACC/g; MariTide is a call option, not the thesis
A5: Viking (VKTX) solo | B5: 31.33 | C5: 16.44 | D5: $8–35 | E5: -0.47531567 | F5: VK2735 sub-q PoS x peak x dilution; partner/takeout is the real value path
A7: VKTX scenarios ($/sh): | B7: Solo (dil.) $16.44 | Partnership $16.06 | Acquisition $34.93
A9: Verdict & what would change my mind
A10: AMGN | B10: BASE ~$282 vs $339 (-17%). A low-beta megacap discounted at ~7% still doesn't screen cheap once you erode Prolia/Xgeva and risk-adjust MariTide. This is a HOLD-quality name, not a GLP-1 growth call. CHANGE MY MIND: MariTide Phase-3 CV-outcomes data that supports >$8bn peak AND clean tolerability (fixing the P2 GI/discontinuation problem) — that would justify raising PoS toward 70% and peak.
A11: VKTX | B11: Solo rNPV ~$16 is BELOW the $31 price; the stock is priced for the partnership/takeout outcome (~$35), consistent with the Metsera bidding war. The Street's $80–102 targets embed ~$20bn peak + high PoS + no dilution — three things at once. RED FLAG on any >50% upside print: it is driven almost entirely by sub-q PoS x peak. CHANGE MY MIND: positive VANQUISH-1/2 topline (de-risks PoS to ~90%) or a signed partner/takeout that removes the financing overhang and dilution.
A13: Red-flag check (per hard rules): | B13: AMGN base -17% and VKTX solo -48% are within +/-50%. VKTX acquisition scenario exceeds +50% by design — single driver is sub-q PoS x peak, disclosed on Sensitivity tab.

Sheet Subsector_Overview
A1: GLP-1 / Obesity Subsector — Overview (ex-LLY, ex-NVO)
A3: 1a. GLP-1 / Anti-Obesity TAM — show the RANGE, not one number
A4: Source | B4: TAM estimate | C4: Year | D4: Scope note
A5: Goldman Sachs Research | B5: $95–100 bn | C5: 2030 | D5: Anti-obesity drugs (addressable)
A6: Morgan Stanley Research | B6: $150 bn (obesity) / $190 bn incl. T2D | C6: 2035 | D6: Obesity + diabetes GLP-1
A7: Grand View Research | B7: $48.8 bn | C7: 2030 | D7: GLP-1 weight-loss drugs (narrower)
A8: Future Market Insights | B8: $39.5 bn | C8: 2030 | D8: Obesity-GLP-1 only
A9: Precedence Research | B9: $66.6 bn | C9: 2035 | D9: Obesity-GLP-1
A10: Goldman (bear note) | B10: Market 'may be smaller than expected' | C10: — | D10: Pricing/persistence downside
A11: Range 2030: ~$40bn (narrow scope) to ~$100bn (broad). Dispersion is driven by scope (obesity-only vs incl. T2D), net-pricing assumptions, and persistence. Use the RANGE.
A13: 1b. Competitive map (ex-LLY / ex-NVO) — the 'everyone else' cohort
A14: Company (ticker) | B14: Lead asset | C14: Mechanism | D14: Furthest phase (mid-2026) | E14: Expected launch | F14: Note
A15: Amgen (AMGN) | B15: MariTide (maridebart cafraglutide) | C15: GLP-1 agonist / GIPR antagonist, monthly | D15: Phase 3 (MARITIME enrolling) | E15: ~2030 | F15: Monthly dosing edge; P2 GI tolerability an issue
A16: Viking Thx (VKTX) | B16: VK2735 sub-q | C16: GLP-1/GIP dual agonist, weekly | D16: Phase 3 (VANQUISH-1/2 enrolled) | E16: ~2028 | F16: Fully enrolled; needs capital/partner
A17: Viking Thx (VKTX) | B17: VK2735 oral | C17: GLP-1/GIP dual agonist, oral | D17: Phase 3 start 4Q26 | E17: ~2030–31 | F17: P2 VENTURE-Oral up to ~12% at 13 wks
A18: Structure Thx (GPCR) | B18: Aleniglipron (GSBR-1290) | C18: Oral small-molecule GLP-1 | D18: Phase 3 (advancing) | E18: ~2029–30 | F18: Oral small molecule = scalable/cheap
A19: Roche (RHHBY) | B19: CT-388 (enicepatide) | C19: GLP-1/GIP dual agonist, sub-q | D19: Phase 3 (starting) | E19: ~2029–30 | F19: + petrelintide (amylin) combo optionality
A20: AstraZeneca (AZN) | B20: AZD5004 | C20: Oral small-molecule GLP-1 | D20: Phase 2b (VISTA/SOLSTICE) | E20: ~2030+ | F20: Licensed from Eccogene; + amylin AZD6234
A21: Zealand/Boehringer | B21: Survodutide (BI 456906) | C21: GLP-1/glucagon dual agonist | D21: Phase 3 | E21: ~2027–28 | F21: MASH + obesity; ~85% achieved >=5% loss
A23: 1c. Subsector BEAR case (one paragraph)
A24: The ex-LLY/NVO cohort is fighting for a SHARE of a market already owned by two entrenched incumbents with manufacturing scale, formulary lock-in and 3–4 year head starts. Three structural threats compress the prize: (1) PRICING — U.S. net prices are already falling as LLY/NVO discount cash-pay and cut deals; a 3rd–7th entrant has no pricing power and competes on rebates. (2) IRA / CMS — GLP-1s are prime Medicare price-negotiation targets; semaglutide is already in the CMS pipeline, and any class read-through caps the back half of every DCF. (3) ORAL COMMODITIZATION — a wave of oral small molecules (GPCR, AZN, oral VK2735, LLY orforglipron) turns 'oral convenience' from a differentiator into table stakes and drives price/patient down. Net: the TAM can hit $100bn and the #3–#7 players still earn mediocre risk-adjusted returns. Every model here should assume share, not the whole market.

Sheet AMGN_FCFF
A1: AMGN — FCFF 10-yr DCF (base business + risk-adj. MariTide)
A3: Key assumptions (yellow = input)
A4: Base business ex-Prolia/Xgeva, 2025 ($M) | B4: 30800 | D4: FY25 rev $36.8bn less ~$6.0bn Prolia+Xgeva
A5: Prolia+Xgeva 2025 revenue ($M) | B5: 6000 | D5: Approx; US LOE Feb-25, biosims launched mid-25
A6: Base business growth (yr1, fades) | B6: 0.045 | D6: Repatha/Eylea-biosim/Eng/onc; fades to ~2%
A7: Base business growth (yr10) | B7: 0.02 | D7: Mature
A8: Prolia+Xgeva erosion / yr | B8: -0.22 | D8: Biosimilar erosion, US + ex-US
A9: MariTide UNADJUSTED peak sales ($M) | B9: 5000 | D9: Adversarial: share of ~$100bn TAM, monthly niche
A10: MariTide Probability of Success | B10: 0.6 | D10: P3 asset, P2 data in hand; 60% (low end of 60-70%) for GI tol#
A11: MariTide launch year | B11: 2030 | D11: P3 MARITIME 72-wk; data ~27-28, launch ~30
A12: GAAP EBIT margin 2025 | B12: 0.247 | D12: 9,080/36,766 (GAAP; depressed by amortization)
A13: GAAP EBIT margin 2035 | B13: 0.3 | D13: Expands as Horizon intangible amort rolls off
A14: D&A 2025 ($M) | B14: 5500 | D14: Est. from 10-Q quarterly (amort ~4.6bn + deprec ~0.9bn)
A15: D&A decline / yr | B15: -0.04 | D15: Intangible amortization runs off
... A21: Exit EV/EBITDA (x) | B21: 11 | D21: Lg-cap biopharma exit multiple
A23: FCFF PROJECTION ($M)
A24: Line \ Year | B24: 2026 | C24: 2027 | D24: 2028 | E24: 2029 | F24: 2030 | G24: 2031 | H24: 2032 | I24: 2033 | J24: 2034 | K24: 2035
A25: Base business ex-P/X | B25: =B4*(1+B6) | C25: =B25*(1+(B6+(B7-B6)*0.1111)) | D25: =C25*(1+(B6+(B7-B6)*0.2222)) | E25: =D25*(1+(B6+(B7-B6)*0.3333)) | F25: =E25*(1+(B6+(B7-B6)*0.4444)) | G25: =F25*(1+(B6+(B7-B6)*0.5556)) | H25: =G25*(1+(B6+(B7-B6)*0.6667)) | I25: =H25*(1+(B6+(B7-B6)*0.7778)) | J25: =I25*(1+(B6+(B7-B6)*0.8889)) | K25: =J25*(1+(B6+(B7-B6)*1.0000))
A26: Prolia + Xgeva (eroding) | B26: =B5*(1+B8) | C26: =B26*(1+B8) | D26: =C26*(1+B8) | E26: =D26*(1+B8) | F26: =E26*(1+B8) | G26: =F26*(1+B8) | H26: =G26*(1+B8) | I26: =H26*(1+B8) | J26: =I26*(1+B8) | K26: =J26*(1+B8)
A27: MariTide (unadjusted) | B27: =IF(2026<B11,0,MIN(B9,B9*(2026-B11+1)/6)) | C27: =IF(2027<B11,0,MIN(B9,B9*(2027-B11+1)/6)) | D27: =IF(2028<B11,0,MIN(B9,B9*(2028-B11+1)/6)) | E27: =IF(2029<B11,0,MIN(B9,B9*(2029-B11+1)/6)) | F27: =IF(2030<B11,0,MIN(B9,B9*(2030-B11+1)/6)) | G27: =IF(2031<B11,0,MIN(B9,B9*(2031-B11+1)/6)) | H27: =IF(2032<B11,0,MIN(B9,B9*(2032-B11+1)/6)) | I27: =IF(2033<B11,0,MIN(B9,B9*(2033-B11+1)/6)) | J27: =IF(2034<B11,0,MIN(B9,B9*(2034-B11+1)/6)) | K27: =IF(2035<B11,0,MIN(B9,B9*(2035-B11+1)/6))
A28: MariTide (x PoS) | B28: =B27*B10 | C28: =C27*B10 | D28: =D27*B10 | E28: =E27*B10 | F28: =F27*B10 | G28: =G27*B10 | H28: =H27*B10 | I28: =I27*B10 | J28: =J27*B10 | K28: =K27*B10
A29: Total revenue | B29: =B25+B26+B28 | C29: =C25+C26+C28 | D29: =D25+D26+D28 | E29: =E25+E26+E28 | F29: =F25+F26+F28 | G29: =G25+G26+G28 | H29: =H25+H26+H28 | I29: =I25+I26+I28 | ... K29: =K25+K26+K28
A30: EBIT margin | B30: =B12+(B13-B12)*0.0000 | C30: =B12+(B13-B12)*0.1111 | D30: =B12+(B13-B12)*0.2222 | E30: =B12+(B13-B12)*0.3333 | F30: =B12+(B13-B12)*0.4444 | G30: =B12+(B13-B12)*0.5556 | H30: =B12+(B13-B12)*0.6667 | I30: =B12+(B13-B12)*0.7778 | J30: =B12+(B13-B12)*0.8889 | K30: =B12+(B13-B12)*1.0000
A31: EBIT | B31: =B29*B30 | C31: =C29*C30 | D31: =D29*D30 | E31: =E29*E30 | F31: =F29*F30 | G31: =G29*G30 | H31: =H29*H30 | I31: =I29*I30 | ... K31: =K29*K30
A32: NOPAT = EBIT*(1-t) | B32: =B31*(1-B19) | C32: =C31*(1-B19) | D32: =D31*(1-B19) | E32: =E31*(1-B19) | F32: =F31*(1-B19) | G32: =G31*(1-B19) | H32: =H31*(1-B19) | I32: =I31*(1-B19) | J32: =J31*(1-B19) | K32: =K31*(1-B19)
A33: + D&A | B33: =B14*(1+B15)^1 | C33: =B14*(1+B15)^2 | D33: =B14*(1+B15)^3 | E33: =B14*(1+B15)^4 | F33: =B14*(1+B15)^5 | G33: =B14*(1+B15)^6 | H33: =B14*(1+B15)^7 | I33: =B14*(1+B15)^8 | J33: =B14*(1+B15)^9 | K33: =B14*(1+B15)^10
A34: - Capex | B34: =B16*(1+B17)^1 | C34: =B16*(1+B17)^2 | D34: =B16*(1+B17)^3 | E34: =B16*(1+B17)^4 | F34: =B16*(1+B17)^5 | G34: =B16*(1+B17)^6 | H34: =B16*(1+B17)^7 | I34: =B16*(1+B17)^8 | J34: =B16*(1+B17)^9 | K34: =B16*(1+B17)^10
A35: - Delta NWC | B35: =(B29-(B4+B5))*B18 | C35: =(C29-B29)*B18 | D35: =(D29-C29)*B18 | E35: =(E29-D29)*B18 | F35: =(F29-E29)*B18 | G35: =(G29-F29)*B18 | H35: =(H29-G29)*B18 | I35: =(I29-H29)*B18 | J35: =(J29-I29)*B18 | K35: =(K29-J29)*B18
A36: FCFF | B36: =B32+B33-B34-B35 | C36: =C32+C33-C34-C35 | D36: =D32+D33-D34-D35 | E36: =E32+E33-E34-E35 | F36: =F32+F33-F34-F35 | G36: =G32+G33-G34-G35 | H36: =H32+H33-H34-H35 | I36: =I32+I33-I34-I35 | ... K36: =K32+K33-K34-K35
A37: Discount factor | B37: =1/(1+AMGN_WACC!B24)^1 | C37: =1/(1+AMGN_WACC!B24)^2 | D37: =1/(1+AMGN_WACC!B24)^3 | E37: =1/(1+AMGN_WACC!B24)^4 | F37: =1/(1+AMGN_WACC!B24)^5 | G37: =1/(1+AMGN_WACC!B24)^6 | H37: =1/(1+AMGN_WACC!B24)^7 | I37: =1/(1+AMGN_WACC!B24)^8 | J37: =1/(1+AMGN_WACC!B24)^9 | K37: =1/(1+AMGN_WACC!B24)^10
A38: PV of FCFF | B38: =B36*B37 | C38: =C36*C37 | D38: =D36*D37 | E38: =E36*E37 | F38: =F36*F37 | G38: =G36*G37 | H38: =H36*H37 | I38: =I36*I37 | ... K38: =K36*K37
A40: VALUATION BRIDGE
A41: Sum PV of explicit FCFF (2026-35) | B41: =SUM(B38:K38)
A42: Terminal value (Gordon g) | B42: =K36*(1+B20)/(AMGN_WACC!B24-B20)
A43: PV of terminal (Gordon) | B43: =B42*K37
A44: Enterprise value (Gordon) | B44: =B41+B43
A45: 2035 EBITDA (EBIT+D&A) | B45: =K31+K33
A46: Terminal value (exit EV/EBITDA) | B46: =B45*B21
A47: PV of terminal (exit mult) | B47: =B46*K37
A48: Enterprise value (exit mult) | B48: =B41+B47
...

Sheet AMGN_WACC
A1: AMGN — WACC (all inputs shown, no black boxes)
A3: Cost of Equity — CAPM | B3: Value | C3: Note
A4: Risk-free rate (10Y UST, 1-Jul-2026) | B4: 0.0446 | C4: TradingEconomics/Treasury, 4.46%
A5: Beta — Yahoo 5Y monthly (reported) | B5: 0.46 | C5: Yahoo Finance key stats; looks low for a lg-cap biopharma
A6: Beta — used (industry-adjusted) | B6: 0.7 | C6: Lg-cap biopharma peer beta ~0.6-0.8; 0.46 rejected as too low
A7: Equity risk premium (used) | B7: 0.05 | C7: Damodaran implied 4.23% (Jan-26); 5.0% used = conservative
A8: Cost of equity = Rf + beta*ERP | B8: =B4+B6*B7
A10: Cost of Debt | B10: Value | C10: Note
A11: Net interest expense FY25 ($M) | B11: 2755 | C11: AMGN FY25 10-K
A12: Avg total debt ($M) [(60.1bn+54.6bn)/2] | B12: 57350 | C12: FY24 $60.1bn, FY25 $54.6bn
A13: Pre-tax cost of debt = IntExp/AvgDebt | B13: =B11/B12 | C13: Cross-check: recent AMGN bond yields ~5.0-5.4%
A14: Marginal tax rate | B14: 0.21 | C14: US fed+state marginal (effective 14.1% is lower)
A15: After-tax cost of debt | B15: =B13*(1-B14)
A17: Capital weights (MARKET value) | B17: $M | C17: Note
A18: Market cap (equity) 539.07M sh x ~$339 | B18: 182700 | C18: companiesmarketcap Jun-26; mkt cap $182.5bn
A19: Total debt (FY25) | B19: 54600 | C19: AMGN FY25 10-K, $54.6bn
A20: Total capital | B20: =B18+B19
A21: Weight equity | B21: =B18/B20
A22: Weight debt | B22: =B19/B20
A24: WACC = We*Ke + Wd*Kd(1-t) | B24: =B21*B8+B22*B15
A26: Note: a low-beta megacap mechanically yields a low WACC (~7%). Base case uses this; Sensitivity tab stresses WACC 6.5%-8.5%. We deliberately reject the 0.46 reported beta in favour of 0.70 to avoid an artificially low discount rate.

Sheet VKTX_rNPV_FCFF
A1: VKTX — rNPV (NOT a normal DCF): VK2735 sub-q + oral, risk-adjusted
A3: Assumptions (yellow = input). Revenue = 0 today; value is entirely optionality.
A4: Sub-q UNADJUSTED peak sales ($M) | B4: 6000 | D4: Adversarial base; Street bull ~$21.6bn franchise
A5: Sub-q Probability of Success | B5: 0.6 | D5: P3 obesity, fully enrolled; 60% (band 55-65%)
A6: Sub-q launch year | B6: 2028 | D6: VANQUISH data 26-27, filing 27, launch 28
A7: Sub-q years to peak | B7: 7 | D7: 6-8yr ramp
A8: Oral UNADJUSTED peak sales ($M) | B8: 3000 | D8: Oral commoditizes; lower price/patient
A9: Oral Probability of Success | B9: 0.4 | D9: Entering P3; 40% (band 35-45%)
A10: Oral launch year | B10: 2031 | D10: P3 starts 4Q26
A11: Oral years to peak | B11: 7 | D11: 6-8yr ramp
A12: Patent-cliff erosion start (yrs post-launch) | B12: 10 | D12: LoE ~10yr post-launch
A13: Erosion rate / yr after cliff | B13: -0.3 | D13: Biosimilar/generic
A14: COGS % of sales | B14: 0.15 | D14: Peptide/oral blended
A15: SG&A % of sales (launch-heavy) | B15: 0.35 | D15: Solo commercial build
... A22: Dilution to fund (new shares M) | B22: 60 | D22: Needs ~$2bn: equity raises pre-profit
A24: SUB-Q VK2735 ($M) | B24: 2026 | C24: 2027 | D24: 2028 | E24: 2029 | F24: 2030 | G24: 2031 | H24: 2032 | I24: 2033 | J24: 2034 | K24: 2035 | L24: 2036 | M24: 2037 | N24: 2038 | O24: 2039 | P24: 2040
A25: Unadj. sales | B25: =IF(2026<B6,0,IF(2026-B6+1<=B7,B4*(2026-B6+1)/B7,B4*(1+B13)^MAX(0,2026-B6+1-B12)))) | C25: =IF(2027<B6,0,IF(2027-B6+1<=B7,B4*(2027-B6+1)/B7,B4*(1+B13)^MAX(0,2027-B6+1-B12)))) | D25: =IF(2028<B6,0,IF(2028-B6+1<=B7,B4*(2028-B6+1)/B7,B4*(1+B13)^MAX(0,2028-B6+1-B12)))) | E25: =IF(2029<B6,0,IF(2029-B6+1<=B7,B4*(2029-B6+1)/B7,B4*(1+B13)^MAX(0,2029-B6+1-B12)))) | F25: =IF(2030<B6,0,IF(2030-B6+1<=B7,B4*(2030-B6+1)/B7,B4*(1+B13)^MAX(0,2030-B6+1-B12)))) | G25: =IF(2031<B6,0,IF(2031-B6+1<=B7,B4*(2031-B6+1)/B7,B4*(1+B13)^MAX(0,2031-B6+1-B12)))) | H25: =IF(2032<B6,0,IF(2032-B6+1<=B7,B4*(2032-B6+1)/B7,B4*(1+B13)^MAX(0,2032-B6+1-B12)))) | I25: =IF(2033<B6,0,IF(2033-B6+1<=B7,B4*(2033-B6+1)/B7,B4*(1+B13)^MAX(0,2033-B6+1-B12)))) | J25: =IF(2034<B6,0,IF(2034-B6+1<=B7,B4*(2034-B6+1)/B7,B4*(1+B13)^MAX(0,2034-B6+1-B12)))) | K25: =IF(2035<B6,0,IF(2035-B6+1<=B7,B4*(2035-B6+1)/B7,B4*(1+B13)^MAX(0,2035-B6+1-B12)))) | L25: =IF(2036<B6,0,IF(2036-B6+1<=B7,B4*(2036-B6+1)/B7,B4*(1+B13)^MAX(0,2036-B6+1-B12)))) | M25: =IF(2037<B6,0,IF(2037-B6+1<=B7,B4*(2037-B6+1)/B7,B4*(1+B13)^MAX(0,2037-B6+1-B12)))) | N25: =IF(2038<B6,0,IF(2038-B6+1<=B7,B4*(2038-B6+1)/B7,B4*(1+B13)^MAX(0,2038-B6+1-B12)))) | O25: =IF(2039<B6,0,IF(2039-B6+1<=B7,B4*(2039-B6+1)/B7,B4*(1+B13)^MAX(0,2039-B6+1-B12)))) | P25: =IF(2040<B6,0,IF(2040-B6+1<=B7,B4*(2040-B6+1)/B7,B4*(1+B13)^MAX(0,2040-B6+1-B12))))
A26: x PoS sales | B26: =B25*B5 | C26: =C25*B5 | D26: =D25*B5 | E26: =E25*B5 | F26: =F25*B5 | G26: =G25*B5 | H26: =H25*B5 | I26: =I25*B5 | J26: =J25*B5 | K26: =K25*B5 | L26: =L25*B5 | M26: =M25*B5 | N26: =N25*B5 | O26: =O25*B5 | P26: =P25*B5
A27: EBIT | B27: =IF(2026<B6,IF(2026>=2026,-B17,0),B26*(1-B14-B15-B16)) | C27: =IF(2027<B6,IF(2027>=2026,-B17,0),C26*(1-B14-B15-B16)) | D27: =IF(2028<B6,IF(2028>=2026,-B17,0),D26*(1-B14-B15-B16)) | E27: =IF(2029<B6,IF(2029>=2026,-B17,0),E26*(1-B14-B15-B16)) | F27: =IF(2030<B6,IF(2030>=2026,-B17,0),F26*(1-B14-B15-B16)) | G27: =IF(2031<B6,IF(2031>=2026,-B17,0),G26*(1-B14-B15-B16)) | H27: =IF(2032<B6,IF(2032>=2026,-B17,0),H26*(1-B14-B15-B16)) | I27: =IF(2033<B6,IF(2033>=2026,-B17,0),I26*(1-B14-B15-B16)) | J27: =IF(2034<B6,IF(2034>=2026,-B17,0),J26*(1-B14-B15-B16)) | K27: =IF(2035<B6,IF(2035>=2026,-B17,0),K26*(1-B14-B15-B16)) | L27: =IF(2036<B6,IF(2036>=2026,-B17,0),L26*(1-B14-B15-B16)) | M27: =IF(2037<B6,IF(2037>=2026,-B17,0),M26*(1-B14-B15-B16)) | N27: =IF(2038<B6,IF(2038>=2026,-B17,0),N26*(1-B14-B15-B16)) | O27: =IF(2039<B6,IF(2039>=2026,-B17,0),O26*(1-B14-B15-B16)) | P27: =IF(2040<B6,IF(2040>=2026,-B17,0),P26*(1-B14-B15-B16))
A28: FCFF (risk-adj) | B28: =IF(B27>0,B27*(1-B19),B27) | C28: =IF(C27>0,C27*(1-B19),C27) | D28: =IF(D27>0,D27*(1-B19),D27) | E28: =IF(E27>0,E27*(1-B19),E27) | F28: =IF(F27>0,F27*(1-B19),F27) | G28: =IF(G27>0,G27*(1-B19),G27) | H28: =IF(H27>0,H27*(1-B19),H27) | I28: =IF(I27>0,I27*(1-B19),I27) | J28: =IF(J27>0,J27*(1-B19),J27) | K28: =IF(K27>0,K27*(1-B19),K27) | L28: =IF(L27>0,L27*(1-B19),L27) | M28: =IF(M27>0,M27*(1-B19),M27) | N28: =IF(N27>0,N27*(1-B19),N27) | O28: =IF(O27>0,O27*(1-B19),O27) | P28: =IF(P27>0,P27*(1-B19),P27)
A29: PV of FCFF | B29: =B28/(1+VKTX_WACC!B11)^1 | C29: =C28/(1+VKTX_WACC!B11)^2 | D29: =D28/(1+VKTX_WACC!B11)^3 | E29: =E28/(1+VKTX_WACC!B11)^4 | F29: =F28/(1+VKTX_WACC!B11)^5 | G29: =G28/(1+VKTX_WACC!B11)^6 | H29: =H28/(1+VKTX_WACC!B11)^7 | I29: =I28/(1+VKTX_WACC!B11)^8 | J29: =J28/(1+VKTX_WACC!B11)^9 | K29: =K28/(1+VKTX_WACC!B11)^10 | L29: =L28/(1+VKTX_WACC!B11)^11 | M29: =M28/(1+VKTX_WACC!B11)^12 | N29: =N28/(1+VKTX_WACC!B11)^13 | O29: =O28/(1+VKTX_WACC!B11)^14 | P29: =P28/(1+VKTX_WACC!B11)^15
A31: ORAL VK2735 ($M) | B31: 2026 | C31: 2027 | D31: 2028 | E31: 2029 | F31: 2030 | G31: 2031 | H31: 2032 | I31: 2033 | J31: 2034 | K31: 2035 | L31: 2036 | M31: 2037 | N31: 2038 | O31: 2039 | P31: 2040
A32: Unadj. sales | B32: =IF(2026<B10,0,IF(2026-B10+1<=B11,B8*(2026-B10+1)/B11,B8*(1+B13)^MAX(0,2026-B10+1-B12)))) | C32: =IF(2027<B10,0,IF(2027-B10+1<=B11,B8*(2027-B10+1)/B11,B8*(1+B13)^MAX(0,2027-B10+1-B12)))) | D32: =IF(2028<B10,0,IF(2028-B10+1<=B11,B8*(2028-B10+1)/B11,B8*(1+B13)^MAX(0,2028-B10+1-B12)))) | E32: =IF(2029<B10,0,IF(2029-B10+1<=B11,B8*(2029-B10+1)/B11,B8*(1+B13)^MAX(0,2029-B10+1-B12)))) | F32: =IF(2030<B10,0,IF(2030-B10+1<=B11,B8*(2030-B10+1)/B11,B8*(1+B13)^MAX(0,2030-B10+1-B12)))) | G32: =IF(2031<B10,0,IF(2031-B10+1<=B11,B8*(2031-B10+1)/B11,B8*(1+B13)^MAX(0,2031-B10+1-B12)))) | H32: =IF(2032<B10,0,IF(2032-B10+1<=B11,B8*(2032-B10+1)/B11,B8*(1+B13)^MAX(0,2032-B10+1-B12)))) | I32: =IF(2033<B10,0,IF(2033-B10+1<=B11,B8*(2033-B10+1)/B11,B8*(1+B13)^MAX(0,2033-B10+1-B12)))) | J32: =IF(2034<B10,0,IF(2034-B10+1<=B11,B8*(2034-B10+1)/B11,B8*(1+B13)^MAX(0,2034-B10+1-B12)))) | K32: =IF(2035<B10,0,IF(2035-B10+1<=B11,B8*(2035-B10+1)/B11,B8*(1+B13)^MAX(0,2035-B10+1-B12)))) | L32: =IF(2036<B10,0,IF(2036-B10+1<=B11,B8*(2036-B10+1)/B11,B8*(1+B13)^MAX(0,2036-B10+1-B12)))) | M32: =IF(2037<B10,0,IF(2037-B10+1<=B11,B8*(2037-B10+1)/B11,B8*(1+B13)^MAX(0,2037-B10+1-B12)))) | N32: =IF(2038<B10,0,IF(2038-B10+1<=B11,B8*(2038-B10+1)/B11,B8*(1+B13)^MAX(0,2038-B10+1-B12)))) | O32: =IF(2039<B10,0,IF(2039-B10+1<=B11,B8*(2039-B10+1)/B11,B8*(1+B13)^MAX(0,2039-B10+1-B12)))) | P32: =IF(2040<B10,0,IF(2040-B10+1<=B11,B8*(2040-B10+1)/B11,B8*(1+B13)^MAX(0,2040-B10+1-B12))))
A33: x PoS sales | B33: =B32*B9 | C33: =C32*B9 | D33: =D32*B9 | E33: =E32*B9 | F33: =F32*B9 | G33: =G32*B9 | H33: =H32*B9 | I33: =I32*B9 | J33: =J32*B9 | K33: =K32*B9 | L33: =L32*B9 | M33: =M32*B9 | N33: =N32*B9 | O33: =O32*B9 | P33: =P32*B9
A34: EBIT | B34: =IF(2026<B10,IF(2026>=2026,-B18,0),B33*(1-B14-B15-B16)) | C34: =IF(2027<B10,IF(2027>=2026,-B18,0),C33*(1-B14-B15-B16)) | D34: =IF(2028<B10,IF(2028>=2026,-B18,0),D33*(1-B14-B15-B16)) | E34: =IF(2029<B10,IF(2029>=2026,-B18,0),E33*(1-B14-B15-B16)) | F34: =IF(2030<B10,IF(2030>=2026,-B18,0),F33*(1-B14-B15-B16)) | G34: =IF(2031<B10,IF(2031>=2026,-B18,0),G33*(1-B14-B15-B16)) | H34: =IF(2032<B10,IF(2032>=2026,-B18,0),H33*(1-B14-B15-B16)) | I34: =IF(2033<B10,IF(2033>=2026,-B18,0),I33*(1-B14-B15-B16)) | J34: =IF(2034<B10,IF(2034>=2026,-B18,0),J33*(1-B14-B15-B16)) | K34: =IF(2035<B10,IF(2035>=2026,-B18,0),K33*(1-B14-B15-B16)) | L34: =IF(2036<B10,IF(2036>=2026,-B18,0),L33*(1-B14-B15-B16)) | M34: =IF(2037<B10,IF(2037>=2026,-B18,0),M33*(1-B14-B15-B16)) | N34: =IF(2038<B10,IF(2038>=2026,-B18,0),N33*(1-B14-B15-B16)) | O34: =IF(2039<B10,IF(2039>=2026,-B18,0),O33*(1-B14-B15-B16)) | P34: =IF(2040<B10,IF(2040>=2026,-B18,0),P33*(1-B14-B15-B16))
A35: FCFF (risk-adj) | B35: =IF(B34>0,B34*(1-B19),B34) | C35: =IF(C34>0,C34*(1-B19),C34) | D35: =IF(D34>0,D34*(1-B19),D34) | E35: =IF(E34>0,E34*(1-B19),E34) | F35: =IF(F34>0,F34*(1-B19),F34) | G35: =IF(G34>0,G34*(1-B19),G34) | H35: =IF(H34>0,H34*(1-B19),H34) | I35: =IF(I34>0,I34*(1-B19),I34) | J35: =IF(J34>0,J34*(1-B19),J34) | K35: =IF(K34>0,K34*(1-B19),K34) | L35: =IF(L34>0,L34*(1-B19),L34) | M35: =IF(M34>0,M34*(1-B19),M34) | N35: =IF(N34>0,N34*(1-B19),N34) | O35: =IF(O34>0,O34*(1-B19),O34) | P35: =IF(P34>0,P34*(1-B19),P34)
A36: PV of FCFF | B36: =B35/(1+VKTX_WACC!B11)^1 | C36: =C35/(1+VKTX_WACC!B11)^2 | D36: =D35/(1+VKTX_WACC!B11)^3 | E36: =E35/(1+VKTX_WACC!B11)^4 | F36: =F35/(1+VKTX_WACC!B11)^5 | G36: =G35/(1+VKTX_WACC!B11)^6 | H36: =H35/(1+VKTX_WACC!B11)^7 | I36: =I35/(1+VKTX_WACC!B11)^8 | J36: =J35/(1+VKTX_WACC!B11)^9 | K36: =K35/(1+VKTX_WACC!B11)^10 | L36: =L35/(1+VKTX_WACC!B11)^11 | M36: =M35/(1+VKTX_WACC!B11)^12 | N36: =N35/(1+VKTX_WACC!B11)^13 | O36: =O35/(1+VKTX_WACC!B11)^14 | P36: =P35/(1+VKTX_WACC!B11)^15
A38: rNPV SUMMARY ($M)
A39: PV sub-q (risk-adj) | B39: =SUM(B29:P29)
A40: PV oral (risk-adj) | B40: =SUM(B36:P36)
A41: Pipeline rNPV | B41: =B39+B40
A42: + Net cash | B42: =B20
A43: Equity value (pre-dilution) | B43: =B41+B42
A45: THREE SCENARIOS — value per share
A46: Scenario | B46: Equity $M | C46: Shares M | D46: $/share
A47: 1) Solo launch (dilution-adj) | B47: =B43 | C47: =B21+B22 | D47: =B47/C47
A48: 2) Partnership (royalty+milestones) | B48: =B41*0.55+B20 | C48: =B21 | D48: =B48/C48 | E48: ~55% of pipeline econ; no dilution (partner funds)
A49: 3) Acquisition (Metsera-comp takeout) | B49: =B43*1.4 | C49: =B21 | D49: =B49/C49 | E49: ~40% control premium on rNPV; Pfizer/Metsera went $4.9bn->~$10bn in a bidding war
A51: Current price (29-Apr-26) | B51: 31.33
A52: Capital need is not optional: ~$630M/yr burn vs $603M cash = <1.5yr runway. A raise or partner is the BASE case, not a scenario. Solo economics are diluted by design.

Sheet VKTX_WACC
A1: VKTX — Discount rate (pre-commercial biotech)
A3: A single-stock beta is meaningless for a pre-revenue, event-driven biotech (price = binary trial outcomes, not market co-movement). We therefore build the rate from an industry unlevered beta + an explicit small-cap / execution premium.
A5: Input | B5: Value | C5: Basis
A6: Risk-free (10Y UST, 1-Jul-26) | B6: 0.0446 | C6: 4.46%
A7: Industry beta (pre-comm. biotech, levered) | B7: 1.3 | C7: Biotech/pharma high-risk cohort ~1.1-1.4
A8: Equity risk premium | B8: 0.05 | C8: 5.0% (as AMGN)
A9: CAPM cost of equity = Rf+beta*ERP | B9: =B6+B7*B8
A10: + Small-cap / clinical-execution premium | B10: 0.02 | C10: Single-asset concentration, financing risk
A11: Discount rate used (rNPV) | B11: =B9+B10
A13: Result ~13%. We explicitly REJECT a ~8% WACC for a pre-revenue biotech. Sensitivity tab stresses 11%-14%. No debt in the stack (net cash), so no WACC blend.

Sheet Sensitivity
A1: Sensitivity — AMGN (price) & VKTX (rNPV/share)
A3: AMGN-1: Blended fair value (rows=WACC, cols=terminal g) green>=+15% vs $339, red<=-15%
A4: Base WACC ~7.0%, g=2.25%.
B5: g=1.50% | C5: g=2.00% | D5: g=2.25% | E5: g=2.50%
A6: 6.50% | B6: 288.62 | C6: 303.27 | D6: 311.88 | E6: 321.58
A7: 7.00% | B7: 264.05 | C7: 275.54 | D7: 282.19 | E7: 289.58
A8: 7.50% | B8: 242.83 | C8: 252.01 | D8: 257.26 | E8: 263.03
A9: 8.00% | B9: 224.25 | C9: 231.7 | D9: 235.91 | E9: 240.5
A10: 8.50% | B10: 207.78 | C10: 213.9 | D10: 217.33 | E10: 221.05
A13: AMGN-2: Blended fair value (rows=MariTide PoS, cols=unadj. peak $M)
A14: MariTide moves the needle only modestly — AMGN value is dominated by the base business.
B15: $2bn | C15: $5bn | D15: $8bn | E15: $12bn
A16: PoS 40% | B16: 271.1 | C16: 277.1 | D16: 283.1 | E16: 291.1
A17: PoS 50% | B17: 272.1 | C17: 279.6 | D17: 287.1 | E17: 297.1
A18: PoS 60% | B18: 273.1 | C18: 282.1 | D18: 291.1 | E18: 303.1
A19: PoS 70% | B19: 274.1 | C19: 284.6 | D19: 295.1 | E19: 309.1
A22: VKTX-1: rNPV/share, SOLO (rows=sub-q PoS, cols=sub-q unadj. peak $M; oral scaled)
A23: Base sub-q PoS 60%, peak $6bn. Green>=+15% vs $31.33.
B24: $3bn | C24: $6bn | D24: $9bn | E24: $15bn
A25: PoS 45% | B25: 1.37 | C25: 10 | D25: 18.64 | E25: 35.91
A26: PoS 55% | B26: 3.51 | C26: 14.29 | D26: 25.07 | E26: 46.64
A27: PoS 60% | B27: 4.58 | C27: 16.44 | D27: 28.29 | E27: 52
A28: PoS 65% | B28: 5.66 | C28: 18.58 | D28: 31.51 | E28: 57.36
A31: VKTX-2: rNPV/share, SOLO (rows=WACC, cols=launch slip yrs)
A32: Every year of delay compounds against a pre-revenue name.
B33: +0yr | C33: +1yr | D33: +2yr | E33: +3yr
A34: 11% | B34: 20.1 | C34: 13.21 | D34: 6.81 | E34: 0.77
A35: 12% | B35: 18.14 | C35: 11.48 | D35: 5.37 | E35: -0.33
A36: 13% | B36: 16.37 | C36: 9.94 | D36: 4.1 | E36: -1.27
A37: 14% | B37: 14.78 | C37: 8.57 | D37: 2.99 | E37: -2.08

Sheet Sources
A1: Sources — every external number tagged (filing / publisher + date)
A3: Data point | B3: Source | C3: Date | D3: URL / reference
A4: AMGN FY25 revenue $36.8bn (+10%), op income $9,080M, net income $7,711M, tax 14.1%, capex $1.9bn, OCF $10.0bn, FCF $8.1bn | B4: Amgen Q4/FY2025 press release; FY25 10-K | C4: 3-Feb-2026 | D4: prnewswire.com/news-releases/amgen-reports-fourth-quarter-and-full-year-2025-financial-results-302678171.html ; sec.gov Amgen 10-K FY2025
A5: AMGN net interest expense FY25 $2,755M; FY24 $3,155M | B5: Amgen FY25 10-K | C5: 3-Feb-2026 | D5: sec.gov/Archives/edgar/data/318154 (amgn-20251231.htm)
A6: AMGN total debt $54.6bn (FY25), $60.1bn (FY24); cash $9.1bn (FY25), $12.0bn (FY24) | B6: Amgen 10-K FY25 & FY24 | C6: Feb-2026 / Feb-2025 | D6: sec.gov EDGAR CIK 318154
A7: AMGN Q1'25 revenue $8,149M; Q1 amort $1.2bn, deprec $209M; Q1'26 amort $896M, deprec $220M (D&A basis) | B7: Amgen 10-Q Q1'25 & Q1'26 | C7: 1-May-2026 | D7: sec.gov/Archives/edgar/data/318154 (amgn-20250331.htm; 05/01/2026 10-Q)
A8: AMGN market cap ~$182.5bn; 539.07M shares; price ~$339 (derived); Apr-26 quote $351 | B8: companiesmarketcap / Yahoo Finance | C8: Jun-2026 | D8: companiesmarketcap.com/amgen/marketcap/ ; finance.yahoo.com/quote/AMGN
A9: AMGN beta 0.46 (5Y monthly) | B9: Yahoo Finance key statistics | C9: Jul-2026 | D9: finance.yahoo.com/quote/AMGN/key-statistics/
A10: MariTide Phase 2 ~up to 20% weight loss w/ elevated GI discontinuation; Phase 3 MARITIME enrolling; launch ~2030 | B10: Amgen PR (ADA 2025); FierceBiotech | C10: Jun-2025 | D10: amgen.com/newsroom/press-releases/2025/06/... ; fiercebiotech.com
A11: Prolia/Xgeva US LOE Feb-2025; denosumab biosimilars launched May–Jul 2025 | B11: GaBI / Center for Biosimilars / pharmaphorum | C11: 2025 | D11: gabionline.net ; centerforbiosimilars.com
A12: VKTX cash+STI $603M; 115.9M shares (Mar-26); price $31.33 (29-Apr-26); Q1'26 net loss $158.3M, R&D $150.2M | B12: Viking Q1'26 results / 8-K | C12: 29-Apr-2026 | D12: prnewswire.com/news-releases/viking-therapeutics-reports-first-quarter-2026... ; sec.gov CIK 1607678
A13: VK2735 sub-q Phase 3 VANQUISH-1 (>4,500 pts, enrolled Nov-25) & VANQUISH-2 (~1,000, enrolled Mar-26) | B13: Viking IR / PRNewswire | C13: Mar-2026 | D13: ir.vikingtherapeutics.com/2026-03-26-...VANQUISH-2
A14: VK2735 oral: Phase 2 VENTURE-Oral up to ~12% at 13 wks; Phase 3 oral start expected 4Q26 | B14: Viking PR (ECO 2026); Applied Clinical Trials | C14: May-2026 | D14: prnewswire.com/...venture-oral-dosing-trial...eco-2026
... A20: Equity risk premium: Damodaran implied 4.23% (Jan-26); 5.0% used (conservative) | B20: Aswath Damodaran (NYU Stern) 2026 ERP edition | C20: Jan/Mar-2026 | D20: pages.stern.nyu.edu/~adamodar/ ; ssrn abstract 6361419
A22: UNSOURCED / estimated (flagged, not fabricated): AMGN FY25 D&A total ($5.5bn) estimated from 10-Q quarterly amort+deprec; Prolia+Xgeva 2025 combined revenue (~$6.0bn) approximated; MariTide & VK2735 peak-sales are analyst-triangulated ranges, not company guidance; VKTX consensus peak/PTs are secondary-source and treated as unverified.
